2023-11-08 12:45:20,942 -  INFO [31m[1mWARNING: This is a development server. Do not use it in a production deployment. Use a production WSGI server instead.[0m
 * Running on http://localhost:5000
2023-11-08 12:45:20,942 -  INFO [33mPress CTRL+C to quit[0m
2023-11-08 12:45:20,942 -  INFO  * Restarting with stat
2023-11-08 12:45:22,823 -  WARNING  * Debugger is active!
2023-11-08 12:45:22,832 -  INFO  * Debugger PIN: 442-931-487
2023-11-08 12:46:30,194 -  INFO  * Detected change in 'c:\\Users\\nata.silva\\Documents\\gerenciador-streaming\\Instrumentacao Python\\app.py', reloading
2023-11-08 12:46:30,346 -  INFO  * Restarting with stat
2023-11-08 12:46:32,629 -  WARNING  * Debugger is active!
2023-11-08 12:46:32,644 -  INFO  * Debugger PIN: 442-931-487
2023-11-08 12:49:16,524 -  INFO [31m[1mWARNING: This is a development server. Do not use it in a production deployment. Use a production WSGI server instead.[0m
 * Running on http://localhost:5000
2023-11-08 12:49:16,524 -  INFO [33mPress CTRL+C to quit[0m
2023-11-08 12:49:16,529 -  INFO  * Restarting with stat
2023-11-08 12:49:18,571 -  WARNING  * Debugger is active!
2023-11-08 12:49:18,577 -  INFO  * Debugger PIN: 442-931-487
2023-11-08 12:49:44,799 -  INFO 127.0.0.1 - - [08/Nov/2023 12:49:44] "GET /filmes HTTP/1.1" 200 -
2023-11-08 12:49:45,836 -  INFO 127.0.0.1 - - [08/Nov/2023 12:49:45] "GET /filmes HTTP/1.1" 200 -
2023-11-08 12:49:48,898 -  INFO 127.0.0.1 - - [08/Nov/2023 12:49:48] "GET /filmes/11 HTTP/1.1" 200 -
2023-11-08 12:49:52,673 -  ERROR Exception while exporting Span batch.
Traceback (most recent call last):
  File "C:\Users\nata.silva\AppData\Local\Packages\PythonSoftwareFoundation.Python.3.11_qbz5n2kfra8p0\LocalCache\local-packages\Python311\site-packages\urllib3\connection.py", line 203, in _new_conn
    sock = connection.create_connection(
           ^^^^^^^^^^^^^^^^^^^^^^^^^^^^^
  File "C:\Users\nata.silva\AppData\Local\Packages\PythonSoftwareFoundation.Python.3.11_qbz5n2kfra8p0\LocalCache\local-packages\Python311\site-packages\urllib3\util\connection.py", line 85, in create_connection
    raise err
  File "C:\Users\nata.silva\AppData\Local\Packages\PythonSoftwareFoundation.Python.3.11_qbz5n2kfra8p0\LocalCache\local-packages\Python311\site-packages\urllib3\util\connection.py", line 73, in create_connection
    sock.connect(sa)
ConnectionRefusedError: [WinError 10061] Nenhuma conexão pôde ser feita porque a máquina de destino as recusou ativamente

The above exception was the direct cause of the following exception:

Traceback (most recent call last):
  File "C:\Users\nata.silva\AppData\Local\Packages\PythonSoftwareFoundation.Python.3.11_qbz5n2kfra8p0\LocalCache\local-packages\Python311\site-packages\urllib3\connectionpool.py", line 791, in urlopen
    response = self._make_request(
               ^^^^^^^^^^^^^^^^^^^
  File "C:\Users\nata.silva\AppData\Local\Packages\PythonSoftwareFoundation.Python.3.11_qbz5n2kfra8p0\LocalCache\local-packages\Python311\site-packages\urllib3\connectionpool.py", line 497, in _make_request
    conn.request(
  File "C:\Users\nata.silva\AppData\Local\Packages\PythonSoftwareFoundation.Python.3.11_qbz5n2kfra8p0\LocalCache\local-packages\Python311\site-packages\urllib3\connection.py", line 395, in request
    self.endheaders()
  File "C:\Program Files\WindowsApps\PythonSoftwareFoundation.Python.3.11_3.11.1776.0_x64__qbz5n2kfra8p0\Lib\http\client.py", line 1281, in endheaders
    self._send_output(message_body, encode_chunked=encode_chunked)
  File "C:\Program Files\WindowsApps\PythonSoftwareFoundation.Python.3.11_3.11.1776.0_x64__qbz5n2kfra8p0\Lib\http\client.py", line 1041, in _send_output
    self.send(msg)
  File "C:\Program Files\WindowsApps\PythonSoftwareFoundation.Python.3.11_3.11.1776.0_x64__qbz5n2kfra8p0\Lib\http\client.py", line 979, in send
    self.connect()
  File "C:\Users\nata.silva\AppData\Local\Packages\PythonSoftwareFoundation.Python.3.11_qbz5n2kfra8p0\LocalCache\local-packages\Python311\site-packages\urllib3\connection.py", line 243, in connect
    self.sock = self._new_conn()
                ^^^^^^^^^^^^^^^^
  File "C:\Users\nata.silva\AppData\Local\Packages\PythonSoftwareFoundation.Python.3.11_qbz5n2kfra8p0\LocalCache\local-packages\Python311\site-packages\urllib3\connection.py", line 218, in _new_conn
    raise NewConnectionError(
urllib3.exceptions.NewConnectionError: <urllib3.connection.HTTPConnection object at 0x000002A71EFD9C10>: Failed to establish a new connection: [WinError 10061] Nenhuma conexão pôde ser feita porque a máquina de destino as recusou ativamente

The above exception was the direct cause of the following exception:

Traceback (most recent call last):
  File "C:\Users\nata.silva\AppData\Local\Packages\PythonSoftwareFoundation.Python.3.11_qbz5n2kfra8p0\LocalCache\local-packages\Python311\site-packages\requests\adapters.py", line 486, in send
    resp = conn.urlopen(
           ^^^^^^^^^^^^^
  File "C:\Users\nata.silva\AppData\Local\Packages\PythonSoftwareFoundation.Python.3.11_qbz5n2kfra8p0\LocalCache\local-packages\Python311\site-packages\urllib3\connectionpool.py", line 845, in urlopen
    retries = retries.increment(
              ^^^^^^^^^^^^^^^^^^
  File "C:\Users\nata.silva\AppData\Local\Packages\PythonSoftwareFoundation.Python.3.11_qbz5n2kfra8p0\LocalCache\local-packages\Python311\site-packages\urllib3\util\retry.py", line 515, in increment
    raise MaxRetryError(_pool, url, reason) from reason  # type: ignore[arg-type]
    ^^^^^^^^^^^^^^^^^^^^^^^^^^^^^^^^^^^^^^^^^^^^^^^^^^^
urllib3.exceptions.MaxRetryError: HTTPConnectionPool(host='localhost', port=4318): Max retries exceeded with url: / (Caused by NewConnectionError('<urllib3.connection.HTTPConnection object at 0x000002A71EFD9C10>: Failed to establish a new connection: [WinError 10061] Nenhuma conexão pôde ser feita porque a máquina de destino as recusou ativamente'))

During handling of the above exception, another exception occurred:

Traceback (most recent call last):
  File "C:\Users\nata.silva\AppData\Local\Packages\PythonSoftwareFoundation.Python.3.11_qbz5n2kfra8p0\LocalCache\local-packages\Python311\site-packages\opentelemetry\sdk\trace\export\__init__.py", line 368, in _export_batch
    self.span_exporter.export(self.spans_list[:idx])  # type: ignore
    ^^^^^^^^^^^^^^^^^^^^^^^^^^^^^^^^^^^^^^^^^^^^^^^^
  File "C:\Users\nata.silva\AppData\Local\Packages\PythonSoftwareFoundation.Python.3.11_qbz5n2kfra8p0\LocalCache\local-packages\Python311\site-packages\opentelemetry\exporter\otlp\proto\http\trace_exporter\__init__.py", line 145, in export
    resp = self._export(serialized_data)
           ^^^^^^^^^^^^^^^^^^^^^^^^^^^^^
  File "C:\Users\nata.silva\AppData\Local\Packages\PythonSoftwareFoundation.Python.3.11_qbz5n2kfra8p0\LocalCache\local-packages\Python311\site-packages\opentelemetry\exporter\otlp\proto\http\trace_exporter\__init__.py", line 114, in _export
    return self._session.post(
           ^^^^^^^^^^^^^^^^^^^
  File "C:\Users\nata.silva\AppData\Local\Packages\PythonSoftwareFoundation.Python.3.11_qbz5n2kfra8p0\LocalCache\local-packages\Python311\site-packages\requests\sessions.py", line 637, in post
    return self.request("POST", url, data=data, json=json, **kwargs)
           ^^^^^^^^^^^^^^^^^^^^^^^^^^^^^^^^^^^^^^^^^^^^^^^^^^^^^^^^^
  File "C:\Users\nata.silva\AppData\Local\Packages\PythonSoftwareFoundation.Python.3.11_qbz5n2kfra8p0\LocalCache\local-packages\Python311\site-packages\requests\sessions.py", line 589, in request
    resp = self.send(prep, **send_kwargs)
           ^^^^^^^^^^^^^^^^^^^^^^^^^^^^^^
  File "C:\Users\nata.silva\AppData\Local\Packages\PythonSoftwareFoundation.Python.3.11_qbz5n2kfra8p0\LocalCache\local-packages\Python311\site-packages\requests\sessions.py", line 703, in send
    r = adapter.send(request, **kwargs)
        ^^^^^^^^^^^^^^^^^^^^^^^^^^^^^^^
  File "C:\Users\nata.silva\AppData\Local\Packages\PythonSoftwareFoundation.Python.3.11_qbz5n2kfra8p0\LocalCache\local-packages\Python311\site-packages\requests\adapters.py", line 519, in send
    raise ConnectionError(e, request=request)
requests.exceptions.ConnectionError: HTTPConnectionPool(host='localhost', port=4318): Max retries exceeded with url: / (Caused by NewConnectionError('<urllib3.connection.HTTPConnection object at 0x000002A71EFD9C10>: Failed to establish a new connection: [WinError 10061] Nenhuma conexão pôde ser feita porque a máquina de destino as recusou ativamente'))
2023-11-08 12:49:57,717 -  ERROR Exception while exporting Span batch.
Traceback (most recent call last):
  File "C:\Users\nata.silva\AppData\Local\Packages\PythonSoftwareFoundation.Python.3.11_qbz5n2kfra8p0\LocalCache\local-packages\Python311\site-packages\urllib3\connection.py", line 203, in _new_conn
    sock = connection.create_connection(
           ^^^^^^^^^^^^^^^^^^^^^^^^^^^^^
  File "C:\Users\nata.silva\AppData\Local\Packages\PythonSoftwareFoundation.Python.3.11_qbz5n2kfra8p0\LocalCache\local-packages\Python311\site-packages\urllib3\util\connection.py", line 85, in create_connection
    raise err
  File "C:\Users\nata.silva\AppData\Local\Packages\PythonSoftwareFoundation.Python.3.11_qbz5n2kfra8p0\LocalCache\local-packages\Python311\site-packages\urllib3\util\connection.py", line 73, in create_connection
    sock.connect(sa)
ConnectionRefusedError: [WinError 10061] Nenhuma conexão pôde ser feita porque a máquina de destino as recusou ativamente

The above exception was the direct cause of the following exception:

Traceback (most recent call last):
  File "C:\Users\nata.silva\AppData\Local\Packages\PythonSoftwareFoundation.Python.3.11_qbz5n2kfra8p0\LocalCache\local-packages\Python311\site-packages\urllib3\connectionpool.py", line 791, in urlopen
    response = self._make_request(
               ^^^^^^^^^^^^^^^^^^^
  File "C:\Users\nata.silva\AppData\Local\Packages\PythonSoftwareFoundation.Python.3.11_qbz5n2kfra8p0\LocalCache\local-packages\Python311\site-packages\urllib3\connectionpool.py", line 497, in _make_request
    conn.request(
  File "C:\Users\nata.silva\AppData\Local\Packages\PythonSoftwareFoundation.Python.3.11_qbz5n2kfra8p0\LocalCache\local-packages\Python311\site-packages\urllib3\connection.py", line 395, in request
    self.endheaders()
  File "C:\Program Files\WindowsApps\PythonSoftwareFoundation.Python.3.11_3.11.1776.0_x64__qbz5n2kfra8p0\Lib\http\client.py", line 1281, in endheaders
    self._send_output(message_body, encode_chunked=encode_chunked)
  File "C:\Program Files\WindowsApps\PythonSoftwareFoundation.Python.3.11_3.11.1776.0_x64__qbz5n2kfra8p0\Lib\http\client.py", line 1041, in _send_output
    self.send(msg)
  File "C:\Program Files\WindowsApps\PythonSoftwareFoundation.Python.3.11_3.11.1776.0_x64__qbz5n2kfra8p0\Lib\http\client.py", line 979, in send
    self.connect()
  File "C:\Users\nata.silva\AppData\Local\Packages\PythonSoftwareFoundation.Python.3.11_qbz5n2kfra8p0\LocalCache\local-packages\Python311\site-packages\urllib3\connection.py", line 243, in connect
    self.sock = self._new_conn()
                ^^^^^^^^^^^^^^^^
  File "C:\Users\nata.silva\AppData\Local\Packages\PythonSoftwareFoundation.Python.3.11_qbz5n2kfra8p0\LocalCache\local-packages\Python311\site-packages\urllib3\connection.py", line 218, in _new_conn
    raise NewConnectionError(
urllib3.exceptions.NewConnectionError: <urllib3.connection.HTTPConnection object at 0x000002A72001CC10>: Failed to establish a new connection: [WinError 10061] Nenhuma conexão pôde ser feita porque a máquina de destino as recusou ativamente

The above exception was the direct cause of the following exception:

Traceback (most recent call last):
  File "C:\Users\nata.silva\AppData\Local\Packages\PythonSoftwareFoundation.Python.3.11_qbz5n2kfra8p0\LocalCache\local-packages\Python311\site-packages\requests\adapters.py", line 486, in send
    resp = conn.urlopen(
           ^^^^^^^^^^^^^
  File "C:\Users\nata.silva\AppData\Local\Packages\PythonSoftwareFoundation.Python.3.11_qbz5n2kfra8p0\LocalCache\local-packages\Python311\site-packages\urllib3\connectionpool.py", line 845, in urlopen
    retries = retries.increment(
              ^^^^^^^^^^^^^^^^^^
  File "C:\Users\nata.silva\AppData\Local\Packages\PythonSoftwareFoundation.Python.3.11_qbz5n2kfra8p0\LocalCache\local-packages\Python311\site-packages\urllib3\util\retry.py", line 515, in increment
    raise MaxRetryError(_pool, url, reason) from reason  # type: ignore[arg-type]
    ^^^^^^^^^^^^^^^^^^^^^^^^^^^^^^^^^^^^^^^^^^^^^^^^^^^
urllib3.exceptions.MaxRetryError: HTTPConnectionPool(host='localhost', port=4318): Max retries exceeded with url: / (Caused by NewConnectionError('<urllib3.connection.HTTPConnection object at 0x000002A72001CC10>: Failed to establish a new connection: [WinError 10061] Nenhuma conexão pôde ser feita porque a máquina de destino as recusou ativamente'))

During handling of the above exception, another exception occurred:

Traceback (most recent call last):
  File "C:\Users\nata.silva\AppData\Local\Packages\PythonSoftwareFoundation.Python.3.11_qbz5n2kfra8p0\LocalCache\local-packages\Python311\site-packages\opentelemetry\sdk\trace\export\__init__.py", line 368, in _export_batch
    self.span_exporter.export(self.spans_list[:idx])  # type: ignore
    ^^^^^^^^^^^^^^^^^^^^^^^^^^^^^^^^^^^^^^^^^^^^^^^^
  File "C:\Users\nata.silva\AppData\Local\Packages\PythonSoftwareFoundation.Python.3.11_qbz5n2kfra8p0\LocalCache\local-packages\Python311\site-packages\opentelemetry\exporter\otlp\proto\http\trace_exporter\__init__.py", line 145, in export
    resp = self._export(serialized_data)
           ^^^^^^^^^^^^^^^^^^^^^^^^^^^^^
  File "C:\Users\nata.silva\AppData\Local\Packages\PythonSoftwareFoundation.Python.3.11_qbz5n2kfra8p0\LocalCache\local-packages\Python311\site-packages\opentelemetry\exporter\otlp\proto\http\trace_exporter\__init__.py", line 114, in _export
    return self._session.post(
           ^^^^^^^^^^^^^^^^^^^
  File "C:\Users\nata.silva\AppData\Local\Packages\PythonSoftwareFoundation.Python.3.11_qbz5n2kfra8p0\LocalCache\local-packages\Python311\site-packages\requests\sessions.py", line 637, in post
    return self.request("POST", url, data=data, json=json, **kwargs)
           ^^^^^^^^^^^^^^^^^^^^^^^^^^^^^^^^^^^^^^^^^^^^^^^^^^^^^^^^^
  File "C:\Users\nata.silva\AppData\Local\Packages\PythonSoftwareFoundation.Python.3.11_qbz5n2kfra8p0\LocalCache\local-packages\Python311\site-packages\requests\sessions.py", line 589, in request
    resp = self.send(prep, **send_kwargs)
           ^^^^^^^^^^^^^^^^^^^^^^^^^^^^^^
  File "C:\Users\nata.silva\AppData\Local\Packages\PythonSoftwareFoundation.Python.3.11_qbz5n2kfra8p0\LocalCache\local-packages\Python311\site-packages\requests\sessions.py", line 703, in send
    r = adapter.send(request, **kwargs)
        ^^^^^^^^^^^^^^^^^^^^^^^^^^^^^^^
  File "C:\Users\nata.silva\AppData\Local\Packages\PythonSoftwareFoundation.Python.3.11_qbz5n2kfra8p0\LocalCache\local-packages\Python311\site-packages\requests\adapters.py", line 519, in send
    raise ConnectionError(e, request=request)
requests.exceptions.ConnectionError: HTTPConnectionPool(host='localhost', port=4318): Max retries exceeded with url: / (Caused by NewConnectionError('<urllib3.connection.HTTPConnection object at 0x000002A72001CC10>: Failed to establish a new connection: [WinError 10061] Nenhuma conexão pôde ser feita porque a máquina de destino as recusou ativamente'))
2023-11-08 12:50:00,676 -  INFO 127.0.0.1 - - [08/Nov/2023 12:50:00] "GET /filmes/diretor/Hitchcock HTTP/1.1" 200 -
2023-11-08 12:50:07,720 -  ERROR Exception while exporting Span batch.
Traceback (most recent call last):
  File "C:\Users\nata.silva\AppData\Local\Packages\PythonSoftwareFoundation.Python.3.11_qbz5n2kfra8p0\LocalCache\local-packages\Python311\site-packages\urllib3\connection.py", line 203, in _new_conn
    sock = connection.create_connection(
           ^^^^^^^^^^^^^^^^^^^^^^^^^^^^^
  File "C:\Users\nata.silva\AppData\Local\Packages\PythonSoftwareFoundation.Python.3.11_qbz5n2kfra8p0\LocalCache\local-packages\Python311\site-packages\urllib3\util\connection.py", line 85, in create_connection
    raise err
  File "C:\Users\nata.silva\AppData\Local\Packages\PythonSoftwareFoundation.Python.3.11_qbz5n2kfra8p0\LocalCache\local-packages\Python311\site-packages\urllib3\util\connection.py", line 73, in create_connection
    sock.connect(sa)
ConnectionRefusedError: [WinError 10061] Nenhuma conexão pôde ser feita porque a máquina de destino as recusou ativamente

The above exception was the direct cause of the following exception:

Traceback (most recent call last):
  File "C:\Users\nata.silva\AppData\Local\Packages\PythonSoftwareFoundation.Python.3.11_qbz5n2kfra8p0\LocalCache\local-packages\Python311\site-packages\urllib3\connectionpool.py", line 791, in urlopen
    response = self._make_request(
               ^^^^^^^^^^^^^^^^^^^
  File "C:\Users\nata.silva\AppData\Local\Packages\PythonSoftwareFoundation.Python.3.11_qbz5n2kfra8p0\LocalCache\local-packages\Python311\site-packages\urllib3\connectionpool.py", line 497, in _make_request
    conn.request(
  File "C:\Users\nata.silva\AppData\Local\Packages\PythonSoftwareFoundation.Python.3.11_qbz5n2kfra8p0\LocalCache\local-packages\Python311\site-packages\urllib3\connection.py", line 395, in request
    self.endheaders()
  File "C:\Program Files\WindowsApps\PythonSoftwareFoundation.Python.3.11_3.11.1776.0_x64__qbz5n2kfra8p0\Lib\http\client.py", line 1281, in endheaders
    self._send_output(message_body, encode_chunked=encode_chunked)
  File "C:\Program Files\WindowsApps\PythonSoftwareFoundation.Python.3.11_3.11.1776.0_x64__qbz5n2kfra8p0\Lib\http\client.py", line 1041, in _send_output
    self.send(msg)
  File "C:\Program Files\WindowsApps\PythonSoftwareFoundation.Python.3.11_3.11.1776.0_x64__qbz5n2kfra8p0\Lib\http\client.py", line 979, in send
    self.connect()
  File "C:\Users\nata.silva\AppData\Local\Packages\PythonSoftwareFoundation.Python.3.11_qbz5n2kfra8p0\LocalCache\local-packages\Python311\site-packages\urllib3\connection.py", line 243, in connect
    self.sock = self._new_conn()
                ^^^^^^^^^^^^^^^^
  File "C:\Users\nata.silva\AppData\Local\Packages\PythonSoftwareFoundation.Python.3.11_qbz5n2kfra8p0\LocalCache\local-packages\Python311\site-packages\urllib3\connection.py", line 218, in _new_conn
    raise NewConnectionError(
urllib3.exceptions.NewConnectionError: <urllib3.connection.HTTPConnection object at 0x000002A72001C6D0>: Failed to establish a new connection: [WinError 10061] Nenhuma conexão pôde ser feita porque a máquina de destino as recusou ativamente

The above exception was the direct cause of the following exception:

Traceback (most recent call last):
  File "C:\Users\nata.silva\AppData\Local\Packages\PythonSoftwareFoundation.Python.3.11_qbz5n2kfra8p0\LocalCache\local-packages\Python311\site-packages\requests\adapters.py", line 486, in send
    resp = conn.urlopen(
           ^^^^^^^^^^^^^
  File "C:\Users\nata.silva\AppData\Local\Packages\PythonSoftwareFoundation.Python.3.11_qbz5n2kfra8p0\LocalCache\local-packages\Python311\site-packages\urllib3\connectionpool.py", line 845, in urlopen
    retries = retries.increment(
              ^^^^^^^^^^^^^^^^^^
  File "C:\Users\nata.silva\AppData\Local\Packages\PythonSoftwareFoundation.Python.3.11_qbz5n2kfra8p0\LocalCache\local-packages\Python311\site-packages\urllib3\util\retry.py", line 515, in increment
    raise MaxRetryError(_pool, url, reason) from reason  # type: ignore[arg-type]
    ^^^^^^^^^^^^^^^^^^^^^^^^^^^^^^^^^^^^^^^^^^^^^^^^^^^
urllib3.exceptions.MaxRetryError: HTTPConnectionPool(host='localhost', port=4318): Max retries exceeded with url: / (Caused by NewConnectionError('<urllib3.connection.HTTPConnection object at 0x000002A72001C6D0>: Failed to establish a new connection: [WinError 10061] Nenhuma conexão pôde ser feita porque a máquina de destino as recusou ativamente'))

During handling of the above exception, another exception occurred:

Traceback (most recent call last):
  File "C:\Users\nata.silva\AppData\Local\Packages\PythonSoftwareFoundation.Python.3.11_qbz5n2kfra8p0\LocalCache\local-packages\Python311\site-packages\opentelemetry\sdk\trace\export\__init__.py", line 368, in _export_batch
    self.span_exporter.export(self.spans_list[:idx])  # type: ignore
    ^^^^^^^^^^^^^^^^^^^^^^^^^^^^^^^^^^^^^^^^^^^^^^^^
  File "C:\Users\nata.silva\AppData\Local\Packages\PythonSoftwareFoundation.Python.3.11_qbz5n2kfra8p0\LocalCache\local-packages\Python311\site-packages\opentelemetry\exporter\otlp\proto\http\trace_exporter\__init__.py", line 145, in export
    resp = self._export(serialized_data)
           ^^^^^^^^^^^^^^^^^^^^^^^^^^^^^
  File "C:\Users\nata.silva\AppData\Local\Packages\PythonSoftwareFoundation.Python.3.11_qbz5n2kfra8p0\LocalCache\local-packages\Python311\site-packages\opentelemetry\exporter\otlp\proto\http\trace_exporter\__init__.py", line 114, in _export
    return self._session.post(
           ^^^^^^^^^^^^^^^^^^^
  File "C:\Users\nata.silva\AppData\Local\Packages\PythonSoftwareFoundation.Python.3.11_qbz5n2kfra8p0\LocalCache\local-packages\Python311\site-packages\requests\sessions.py", line 637, in post
    return self.request("POST", url, data=data, json=json, **kwargs)
           ^^^^^^^^^^^^^^^^^^^^^^^^^^^^^^^^^^^^^^^^^^^^^^^^^^^^^^^^^
  File "C:\Users\nata.silva\AppData\Local\Packages\PythonSoftwareFoundation.Python.3.11_qbz5n2kfra8p0\LocalCache\local-packages\Python311\site-packages\requests\sessions.py", line 589, in request
    resp = self.send(prep, **send_kwargs)
           ^^^^^^^^^^^^^^^^^^^^^^^^^^^^^^
  File "C:\Users\nata.silva\AppData\Local\Packages\PythonSoftwareFoundation.Python.3.11_qbz5n2kfra8p0\LocalCache\local-packages\Python311\site-packages\requests\sessions.py", line 703, in send
    r = adapter.send(request, **kwargs)
        ^^^^^^^^^^^^^^^^^^^^^^^^^^^^^^^
  File "C:\Users\nata.silva\AppData\Local\Packages\PythonSoftwareFoundation.Python.3.11_qbz5n2kfra8p0\LocalCache\local-packages\Python311\site-packages\requests\adapters.py", line 519, in send
    raise ConnectionError(e, request=request)
requests.exceptions.ConnectionError: HTTPConnectionPool(host='localhost', port=4318): Max retries exceeded with url: / (Caused by NewConnectionError('<urllib3.connection.HTTPConnection object at 0x000002A72001C6D0>: Failed to establish a new connection: [WinError 10061] Nenhuma conexão pôde ser feita porque a máquina de destino as recusou ativamente'))
2023-11-08 12:50:46,561 -  INFO  * Detected change in 'c:\\Users\\nata.silva\\Documents\\gerenciador-streaming\\Instrumentacao Python\\app.py', reloading
2023-11-08 12:50:46,640 -  INFO  * Restarting with stat
2023-11-08 12:50:48,823 -  WARNING  * Debugger is active!
2023-11-08 12:50:48,832 -  INFO  * Debugger PIN: 442-931-487
